import React from 'react';
import { render, screen } from '@testing-library/react';
import { ErrorBoundary } from '@/components/ui/error-boundary';

const ThrowError = ({ shouldThrow }: { shouldThrow: boolean }) => {
  if (shouldThrow) {
    throw new Error('Test error');
  }
  return <div>No error</div>;
};

describe('ErrorBoundary Component', () => {
  beforeEach(() => {
    jest.spyOn(console, 'error').mockImplementation(() => {});
  });

  afterEach(() => {
    jest.restoreAllMocks();
  });

  it('renders children when no error occurs', () => {
    render(
      <ErrorBoundary>
        <ThrowError shouldThrow={false} />
      </ErrorBoundary>
    );
    expect(screen.getByText('No error')).toBeInTheDocument();
  });

  it('renders error UI when error occurs', () => {
    render(
      <ErrorBoundary>
        <ThrowError shouldThrow={true} />
      </ErrorBoundary>
    );
    expect(screen.getByText(/Algo saliÃ³ mal/)).toBeInTheDocument();
  });

  it('renders custom fallback when provided', () => {
    const CustomFallback = () => <div>Custom error message</div>;
    render(
      <ErrorBoundary fallback={<CustomFallback />}>
        <ThrowError shouldThrow={true} />
      </ErrorBoundary>
    );
    expect(screen.getByText('Custom error message')).toBeInTheDocument();
  });

  it('calls onError callback when error occurs', () => {
    const onError = jest.fn();
    render(
      <ErrorBoundary onError={onError}>
        <ThrowError shouldThrow={true} />
      </ErrorBoundary>
    );
    expect(onError).toHaveBeenCalled();
  });
});
